{"name": "test_create_multiple_users", "status": "failed", "statusDetails": {"message": "AssertionError: assert 400 == 201\n  +400\n  -201", "trace": "@pytest.mark.multiple_user_data01\n    def test_create_multiple_users():\n        # API\n        file = open('/home/adi/Boast/boast_api_test/tests/data_driven_testing/create_multiple_users.json')\n        json_file = json.loads(file.read())\n        # Excel code\n        excel_file = openpyxl.load_workbook('/home/adi/Boast/boast_api_test/tests/data_driven_testing/multiple_users.xlsx')\n        excel_sheet = excel_file['Sheet1']\n        rows = excel_sheet.max_row\n    \n        for i in range(2, rows+1):\n            cell_first_name = excel_sheet.cell(row=i, column=1)\n            cell_last_name = excel_sheet.cell(row=i, column=2)\n            cell_username = excel_sheet.cell(row=i, column=3)\n            cell_email = excel_sheet.cell(row=i, column=4)\n            cell_is_active = excel_sheet.cell(row=i, column=5)\n            cell_nick_name = excel_sheet.cell(row=i, column=6)\n            cell_display_name = excel_sheet.cell(row=i, column=7)\n            cell_calendar_url = excel_sheet.cell(row=i, column=8)\n            cell_mfa_enabled = excel_sheet.cell(row=i, column=9)\n            json_file['first_name'] = cell_first_name.value\n            json_file['last_name'] = cell_last_name.value\n            json_file['username'] = cell_username.value\n            json_file['email'] = cell_email.value\n            json_file['is_active'] = cell_is_active.value\n            json_file['nick_name'] = cell_nick_name.value\n            json_file['display_name'] = cell_display_name.value\n            json_file['calendar_url'] = cell_calendar_url.value\n            json_file['mfa_enabled'] = cell_mfa_enabled.value\n            response = requests.post('http://badger.boast.net:8080/api/users/user/', json=json_file,\n                                     auth=credentials)\n>           assert response.status_code == 201\nE           assert 400 == 201\nE             +400\nE             -201\n\ntests/data_driven_testing/test_add_multiple_users.py:41: AssertionError"}, "attachments": [{"name": "log", "source": "e32afe0a-5983-4c8e-880d-bb620e7cf019-attachment.txt", "type": "text/plain"}], "start": 1611089971184, "stop": 1611089971297, "uuid": "14ff9652-65af-44ef-8a27-4ff0debcd65a", "historyId": "9990b33ed2f3b2c47fe394e0b9b2bcd9", "testCaseId": "97a01137f26401c5af4f05632bd19f39", "fullName": "tests.data_driven_testing.test_add_multiple_users#test_create_multiple_users", "labels": [{"name": "tag", "value": "multiple_user_data01"}, {"name": "parentSuite", "value": "tests.data_driven_testing"}, {"name": "suite", "value": "test_add_multiple_users"}, {"name": "host", "value": "atlas"}, {"name": "thread", "value": "61120-MainThread"}, {"name": "framework", "value": "pytest"}, {"name": "language", "value": "cpython3"}, {"name": "package", "value": "tests.data_driven_testing.test_add_multiple_users"}]}